Workbook

Sheet Summary
A1: Fish On! - PAR sheet (probability accounting report)
A2: v1.0 demo | 5x3, 10 fixed lines | generated 2026-10-07 | design figures, NOT independently certified
A4: Measure | B4: Value | C4: Source
A5: Theoretical RTP (exact, uncapped) | B5: ='Line Wins Base'!E41+'Free Spins Feature'!B20 -> 0.96142489 | C5: Exact from strips (formulas in this workbook)
A6: of which base game line wins | B6: ='Line Wins Base'!E41 -> 0.54140192 | C6: Line Wins Base
A7: of which free spins feature | B7: ='Free Spins Feature'!B20 -> 0.42002297 | C7: Free Spins Feature
A8: Simulated RTP | B8: 0.96059135 | C8: Simulation, 50,000,000 rounds
A9: Simulated RTP 95% confidence (+/-) | B9: 0.0020033258 | C9: 1.96 x SD / sqrt(rounds)
A10: Hit frequency (any line win in base spin) | B10: 0.25495222 | C10: Simulation
A11: Feature frequency: 1 in | B11: ='Free Spins Feature'!B9 -> 151.7037 | C11: Exact
A12: Expected free spins per feature | B12: ='Free Spins Feature'!B14 -> 10.340823 | C12: Exact
A13: Expected feature win (x stake) | B13: ='Free Spins Feature'!B19 -> 63.71904 | C13: Exact (uncapped)
A14: Volatility (standard deviation, x stake) | B14: 7.2273736 | C14: Simulation
A15: Returns below stake (0 < win < 1x) | B15: 0.11144686 | C15: Simulation; not celebrated (RTS 14F)
A16: Highest win in simulation (x stake) | B16: 2066.6 | C16: Simulation
A17: Maximum win cap per round (x stake) | B17: 5000 | C17: engine.js MAX_WIN
A18: Rounds that hit the cap in simulation | B18: 0 | C18: Simulation
A19: Stake range (GB) | B19: £0.10 to £5.00 (£2.00 max for ages 18 to 24) | C19: GB online slots stake limits 2025; operator may set lower
A22: Colour key: blue = input from game files or simulation; black = formula; green = link to another sheet.
A23: Exact figures assume the 5,000x cap is never reached; the simulation never reached it, so the effect is negligible.
A24: Simulation uses the production engine (client/src/engine.js) with a seeded PRNG for repeatability.
A25: Regenerate: node math/par_sheet.mjs 50000000 then python math/par_xlsx.py
A26: This is the developer's design PAR. Certification by a UKGC-approved test house is required before real-money use.

Sheet Paytable
A1: Paytable (line pays)
A2: Units are per line as stored in engine.js; x stake = units / 10 (10 lines, stake = total bet). Wild substitutes for all line symbols.
A4: Symbol | B4: Code | C4: Tier | D4: 3 (units) | E4: 4 (units) | F4: 5 (units) | G4: 3 (x stake) | H4: 4 (x stake) | I4: 5 (x stake)
A5: Float | B5: FLOAT | C5: Low | D5: 6 | E5: 15 | F5: 30 | G5: =D5/10 -> 0.6 | H5: =E5/10 -> 1.5 | I5: =F5/10 -> 3
A6: Boilies | B6: BOILIE | C6: Low | D6: 6 | E6: 15 | F6: 30 | G6: =D6/10 -> 0.6 | H6: =E6/10 -> 1.5 | I6: =F6/10 -> 3
A7: Sweetcorn | B7: CORN | C7: Low | D7: 9 | E7: 24 | F7: 45 | G7: =D7/10 -> 0.9 | H7: =E7/10 -> 2.4 | I7: =F7/10 -> 4.5
A8: Pellets | B8: PELLET | C8: Low | D8: 9 | E8: 24 | F8: 45 | G8: =D8/10 -> 0.9 | H8: =E8/10 -> 2.4 | I8: =F8/10 -> 4.5
A9: Flask | B9: FLASK | C9: Mid | D9: 12 | E9: 30 | F9: 75 | G9: =D9/10 -> 1.2 | H9: =E9/10 -> 3 | I9: =F9/10 -> 7.5
A10: Catapult | B10: CATAPULT | C10: Mid | D10: 15 | E10: 36 | F10: 90 | G10: =D10/10 -> 1.5 | H10: =E10/10 -> 3.6 | I10: =F10/10 -> 9
A11: Landing Net | B11: NET | C11: Mid | D11: 18 | E11: 45 | F11: 120 | G11: =D11/10 -> 1.8 | H11: =E11/10 -> 4.5 | I11: =F11/10 -> 12
A12: Bivvy | B12: BIVVY | C12: Mid | D12: 24 | E12: 60 | F12: 150 | G12: =D12/10 -> 2.4 | H12: =E12/10 -> 6 | I12: =F12/10 -> 15
A13: Roach | B13: ROACH | C13: High | D13: 30 | E13: 75 | F13: 180 | G13: =D13/10 -> 3 | H13: =E13/10 -> 7.5 | I13: =F13/10 -> 18
A14: Bream | B14: BREAM | C14: High | D14: 36 | E14: 90 | F14: 240 | G14: =D14/10 -> 3.6 | H14: =E14/10 -> 9 | I14: =F14/10 -> 24
A15: Tench | B15: TENCH | C15: High | D15: 45 | E15: 120 | F15: 360 | G15: =D15/10 -> 4.5 | H15: =E15/10 -> 12 | I15: =F15/10 -> 36
A16: Mirror Carp | B16: MIRROR | C16: High | D16: 60 | E16: 225 | F16: 750 | G16: =D16/10 -> 6 | H16: =E16/10 -> 22.5 | I16: =F16/10 -> 75
A18: Source: client/src/engine.js PAY table. Five wilds on a line pay as Mirror Carp x5.

Sheet Reel Strips
A1: Reel strip symbol counts and stop probabilities
A2: Counts from client/strips.json (each reel stops uniformly on one of its 32 positions). Probability = count / strip length.
A4: Base game strips
A5: Symbol | B5: Reel 1 | C5: Reel 2 | D5: Reel 3 | E5: Reel 4 | F5: Reel 5 | H5: P reel 1 | I5: P reel 2 | J5: P reel 3 | K5: P reel 4 | L5: P reel 5
A6: Float | B6: 5 | C6: 3 | D6: 3 | E6: 3 | F6: 4 | H6: =B6/B$21 -> 0.15625 | I6: =C6/C$21 -> 0.09375 | J6: =D6/D$21 -> 0.09375 | K6: =E6/E$21 -> 0.09375 | L6: =F6/F$21 -> 0.125
A7: Boilies | B7: 5 | C7: 3 | D7: 3 | E7: 3 | F7: 4 | H7: =B7/B$21 -> 0.15625 | I7: =C7/C$21 -> 0.09375 | J7: =D7/D$21 -> 0.09375 | K7: =E7/E$21 -> 0.09375 | L7: =F7/F$21 -> 0.125
A8: Sweetcorn | B8: 4 | C8: 4 | D8: 4 | E8: 4 | F8: 4 | H8: =B8/B$21 -> 0.125 | I8: =C8/C$21 -> 0.125 | J8: =D8/D$21 -> 0.125 | K8: =E8/E$21 -> 0.125 | L8: =F8/F$21 -> 0.125
A9: Pellets | B9: 4 | C9: 4 | D9: 4 | E9: 4 | F9: 4 | H9: =B9/B$21 -> 0.125 | I9: =C9/C$21 -> 0.125 | J9: =D9/D$21 -> 0.125 | K9: =E9/E$21 -> 0.125 | L9: =F9/F$21 -> 0.125
A10: Flask | B10: 3 | C10: 3 | D10: 3 | E10: 3 | F10: 3 | H10: =B10/B$21 -> 0.09375 | I10: =C10/C$21 -> 0.09375 | J10: =D10/D$21 -> 0.09375 | K10: =E10/E$21 -> 0.09375 | L10: =F10/F$21 -> 0.09375
A11: Catapult | B11: 3 | C11: 2 | D11: 2 | E11: 2 | F11: 3 | H11: =B11/B$21 -> 0.09375 | I11: =C11/C$21 -> 0.0625 | J11: =D11/D$21 -> 0.0625 | K11: =E11/E$21 -> 0.0625 | L11: =F11/F$21 -> 0.09375
A12: Landing Net | B12: 2 | C12: 2 | D12: 2 | E12: 2 | F12: 2 | H12: =B12/B$21 -> 0.0625 | I12: =C12/C$21 -> 0.0625 | J12: =D12/D$21 -> 0.0625 | K12: =E12/E$21 -> 0.0625 | L12: =F12/F$21 -> 0.0625
A13: Bivvy | B13: 2 | C13: 2 | D13: 2 | E13: 2 | F13: 2 | H13: =B13/B$21 -> 0.0625 | I13: =C13/C$21 -> 0.0625 | J13: =D13/D$21 -> 0.0625 | K13: =E13/E$21 -> 0.0625 | L13: =F13/F$21 -> 0.0625
A14: Roach | B14: 1 | C14: 1 | D14: 1 | E14: 1 | F14: 1 | H14: =B14/B$21 -> 0.03125 | I14: =C14/C$21 -> 0.03125 | J14: =D14/D$21 -> 0.03125 | K14: =E14/E$21 -> 0.03125 | L14: =F14/F$21 -> 0.03125
A15: Bream | B15: 1 | C15: 1 | D15: 1 | E15: 1 | F15: 1 | H15: =B15/B$21 -> 0.03125 | I15: =C15/C$21 -> 0.03125 | J15: =D15/D$21 -> 0.03125 | K15: =E15/E$21 -> 0.03125 | L15: =F15/F$21 -> 0.03125
A16: Tench | B16: 1 | C16: 1 | D16: 1 | E16: 1 | F16: 1 | H16: =B16/B$21 -> 0.03125 | I16: =C16/C$21 -> 0.03125 | J16: =D16/D$21 -> 0.03125 | K16: =E16/E$21 -> 0.03125 | L16: =F16/F$21 -> 0.03125
A17: Mirror Carp | B17: 1 | C17: 1 | D17: 1 | E17: 1 | F17: 1 | H17: =B17/B$21 -> 0.03125 | I17: =C17/C$21 -> 0.03125 | J17: =D17/D$21 -> 0.03125 | K17: =E17/E$21 -> 0.03125 | L17: =F17/F$21 -> 0.03125
... A20: Specimen Fish (Cash) | B20: 0 | C20: 0 | D20: 0 | E20: 0 | F20: 0 | H20: =B20/B$21 -> 0 | I20: =C20/C$21 -> 0 | J20: =D20/D$21 -> 0 | K20: =E20/E$21 -> 0 | L20: =F20/F$21 -> 0
A21: Strip length | B21: =SUM(B6:B20) -> 32 | C21: =SUM(C6:C20) -> 32 | D21: =SUM(D6:D20) -> 32 | E21: =SUM(E6:E20) -> 32 | F21: =SUM(F6:F20) -> 32
A23: Free spins strips
A24: Symbol | B24: Reel 1 | C24: Reel 2 | D24: Reel 3 | E24: Reel 4 | F24: Reel 5 | H24: P reel 1 | I24: P reel 2 | J24: P reel 3 | K24: P reel 4 | L24: P reel 5
A25: Float | B25: 3 | C25: 2 | D25: 2 | E25: 2 | F25: 3 | H25: =B25/B$40 -> 0.09375 | I25: =C25/C$40 -> 0.0625 | J25: =D25/D$40 -> 0.0625 | K25: =E25/E$40 -> 0.0625 | L25: =F25/F$40 -> 0.09375
A26: Boilies | B26: 3 | C26: 2 | D26: 2 | E26: 2 | F26: 3 | H26: =B26/B$40 -> 0.09375 | I26: =C26/C$40 -> 0.0625 | J26: =D26/D$40 -> 0.0625 | K26: =E26/E$40 -> 0.0625 | L26: =F26/F$40 -> 0.09375
A27: Sweetcorn | B27: 4 | C27: 3 | D27: 3 | E27: 3 | F27: 3 | H27: =B27/B$40 -> 0.125 | I27: =C27/C$40 -> 0.09375 | J27: =D27/D$40 -> 0.09375 | K27: =E27/E$40 -> 0.09375 | L27: =F27/F$40 -> 0.09375
A28: Pellets | B28: 4 | C28: 3 | D28: 3 | E28: 3 | F28: 3 | H28: =B28/B$40 -> 0.125 | I28: =C28/C$40 -> 0.09375 | J28: =D28/D$40 -> 0.09375 | K28: =E28/E$40 -> 0.09375 | L28: =F28/F$40 -> 0.09375
A29: Flask | B29: 3 | C29: 3 | D29: 3 | E29: 3 | F29: 3 | H29: =B29/B$40 -> 0.09375 | I29: =C29/C$40 -> 0.09375 | J29: =D29/D$40 -> 0.09375 | K29: =E29/E$40 -> 0.09375 | L29: =F29/F$40 -> 0.09375
A30: Catapult | B30: 3 | C30: 2 | D30: 2 | E30: 2 | F30: 3 | H30: =B30/B$40 -> 0.09375 | I30: =C30/C$40 -> 0.0625 | J30: =D30/D$40 -> 0.0625 | K30: =E30/E$40 -> 0.0625 | L30: =F30/F$40 -> 0.09375
A31: Landing Net | B31: 2 | C31: 2 | D31: 2 | E31: 2 | F31: 2 | H31: =B31/B$40 -> 0.0625 | I31: =C31/C$40 -> 0.0625 | J31: =D31/D$40 -> 0.0625 | K31: =E31/E$40 -> 0.0625 | L31: =F31/F$40 -> 0.0625
A32: Bivvy | B32: 2 | C32: 2 | D32: 2 | E32: 2 | F32: 2 | H32: =B32/B$40 -> 0.0625 | I32: =C32/C$40 -> 0.0625 | J32: =D32/D$40 -> 0.0625 | K32: =E32/E$40 -> 0.0625 | L32: =F32/F$40 -> 0.0625
A33: Roach | B33: 1 | C33: 1 | D33: 1 | E33: 1 | F33: 1 | H33: =B33/B$40 -> 0.03125 | I33: =C33/C$40 -> 0.03125 | J33: =D33/D$40 -> 0.03125 | K33: =E33/E$40 -> 0.03125 | L33: =F33/F$40 -> 0.03125
A34: Bream | B34: 1 | C34: 1 | D34: 1 | E34: 1 | F34: 1 | H34: =B34/B$40 -> 0.03125 | I34: =C34/C$40 -> 0.03125 | J34: =D34/D$40 -> 0.03125 | K34: =E34/E$40 -> 0.03125 | L34: =F34/F$40 -> 0.03125
A35: Tench | B35: 1 | C35: 1 | D35: 1 | E35: 1 | F35: 1 | H35: =B35/B$40 -> 0.03125 | I35: =C35/C$40 -> 0.03125 | J35: =D35/D$40 -> 0.03125 | K35: =E35/E$40 -> 0.03125 | L35: =F35/F$40 -> 0.03125
A36: Mirror Carp | B36: 1 | C36: 1 | D36: 1 | E36: 1 | F36: 1 | H36: =B36/B$40 -> 0.03125 | I36: =C36/C$40 -> 0.03125 | J36: =D36/D$40 -> 0.03125 | K36: =E36/E$40 -> 0.03125 | L36: =F36/F$40 -> 0.03125
... A39: Specimen Fish (Cash) | B39: 4 | C39: 4 | D39: 4 | E39: 4 | F39: 4 | H39: =B39/B$40 -> 0.125 | I39: =C39/C$40 -> 0.125 | J39: =D39/D$40 -> 0.125 | K39: =E39/E$40 -> 0.125 | L39: =F39/F$40 -> 0.125
A40: Strip length | B40: =SUM(B25:B39) -> 32 | C40: =SUM(C25:C39) -> 32 | D40: =SUM(D25:D39) -> 32 | E40: =SUM(E25:E39) -> 32 | F40: =SUM(F25:F39) -> 32

Sheet Line Wins Base
A1: Line Wins Base: exact probability per payline
A2: Formula: the first non-wild symbol on the line is the target; wilds before/after it count; the next symbol must break the run. Probabilities come from Reel Strips; RTP contribution = probability x pay (x stake) x 10 lines.
A4: Symbol | B4: Count | C4: P (per line) | D4: Pay (x stake) | E4: RTP contribution | F4: Check: engine exact
A5: Float | B5: 3 | C5: ='Reel Strips'!$H$6*('Reel Strips'!$I$6+'Reel Strips'!$I$18)*('Reel Strips'!$J$6+'Reel Strips'!$J$18)*(1-'Reel Strips'!$K$6-'Reel Strips'!$K$18)+'Reel Strips'!$H$18*'Reel Strips'!$I$6*('Reel Strips'!$J$6+'Reel Strips'!$J$18)*(1-'Reel Strips'!$K$6-'Reel Strips'!$K$18)+'Reel Strips'!$H$18*'Reel Strips'!$I$18*'Reel Strips'!$J$6*(1-'Reel Strips'!$K$6-'Reel Strips'!$K$18) -> 0.0044631958 | D5: =Paytable!G5 -> 0.6 | E5: =C5*D5*10 -> 0.026779175 | F5: 0.0044631958
A6: Float | B6: 4 | C6: ='Reel Strips'!$H$6*('Reel Strips'!$I$6+'Reel Strips'!$I$18)*('Reel Strips'!$J$6+'Reel Strips'!$J$18)*('Reel Strips'!$K$6+'Reel Strips'!$K$18)*(1-'Reel Strips'!$L$6-'Reel Strips'!$L$18)+'Reel Strips'!$H$18*'Reel Strips'!$I$6*('Reel Strips'!$J$6+'Reel Strips'!$J$18)*('Reel Strips'!$K$6+'Reel Strips'!$K$18)*(1-'Reel Strips'!$L$6-'Reel Strips'!$L$18)+'Reel Strips'!$H$18*'Reel Strips'!$I$18*'Reel Strips'!$J$6*('Reel Strips'!$K$6+'Reel Strips'!$K$18)*(1-'Reel Strips'!$L$6-'Reel Strips'!$L$18)+'Reel Strips'!$H$18*'Reel Strips'!$I$18*'Reel Strips'!$J$18*'Reel Strips'!$K$6*(1-'Reel Strips'!$L$6-'Reel Strips'!$L$18) -> 0.00083684921 | D6: =Paytable!H5 -> 1.5 | E6: =C6*D6*10 -> 0.012552738 | F6: 0.00083684921
A7: Float | B7: 5 | C7: ='Reel Strips'!$H$6*('Reel Strips'!$I$6+'Reel Strips'!$I$18)*('Reel Strips'!$J$6+'Reel Strips'!$J$18)*('Reel Strips'!$K$6+'Reel Strips'!$K$18)*('Reel Strips'!$L$6+'Reel Strips'!$L$18)+'Reel Strips'!$H$18*'Reel Strips'!$I$6*('Reel Strips'!$J$6+'Reel Strips'!$J$18)*('Reel Strips'!$K$6+'Reel Strips'!$K$18)*('Reel Strips'!$L$6+'Reel Strips'!$L$18)+'Reel Strips'!$H$18*'Reel Strips'!$I$18*'Reel Strips'!$J$6*('Reel Strips'!$K$6+'Reel Strips'!$K$18)*('Reel Strips'!$L$6+'Reel Strips'!$L$18)+'Reel Strips'!$H$18*'Reel Strips'!$I$18*'Reel Strips'!$J$18*'Reel Strips'!$K$6*('Reel Strips'!$L$6+'Reel Strips'!$L$18)+'Reel Strips'!$H$18*'Reel Strips'!$I$18*'Reel Strips'!$J$18*'Reel Strips'!$K$18*'Reel Strips'!$L$6 -> 0.00019311905 | D7: =Paytable!I5 -> 3 | E7: =C7*D7*10 -> 0.0057935715 | F7: 0.00019311905
A8: Boilies | B8: 3 | C8: ='Reel Strips'!$H$7*('Reel Strips'!$I$7+'Reel Strips'!$I$18)*('Reel Strips'!$J$7+'Reel Strips'!$J$18)*(1-'Reel Strips'!$K$7-'Reel Strips'!$K$18)+'Reel Strips'!$H$18*'Reel Strips'!$I$7*('Reel Strips'!$J$7+'Reel Strips'!$J$18)*(1-'Reel Strips'!$K$7-'Reel Strips'!$K$18)+'Reel Strips'!$H$18*'Reel Strips'!$I$18*'Reel Strips'!$J$7*(1-'Reel Strips'!$K$7-'Reel Strips'!$K$18) -> 0.0044631958 | D8: =Paytable!G6 -> 0.6 | E8: =C8*D8*10 -> 0.026779175 | F8: 0.0044631958
A9: Boilies | B9: 4 | C9: ='Reel Strips'!$H$7*('Reel Strips'!$I$7+'Reel Strips'!$I$18)*('Reel Strips'!$J$7+'Reel Strips'!$J$18)*('Reel Strips'!$K$7+'Reel Strips'!$K$18)*(1-'Reel Strips'!$L$7-'Reel Strips'!$L$18)+'Reel Strips'!$H$18*'Reel Strips'!$I$7*('Reel Strips'!$J$7+'Reel Strips'!$J$18)*('Reel Strips'!$K$7+'Reel Strips'!$K$18)*(1-'Reel Strips'!$L$7-'Reel Strips'!$L$18)+'Reel Strips'!$H$18*'Reel Strips'!$I$18*'Reel Strips'!$J$7*('Reel Strips'!$K$7+'Reel Strips'!$K$18)*(1-'Reel Strips'!$L$7-'Reel Strips'!$L$18)+'Reel Strips'!$H$18*'Reel Strips'!$I$18*'Reel Strips'!$J$18*'Reel Strips'!$K$7*(1-'Reel Strips'!$L$7-'Reel Strips'!$L$18) -> 0.00083684921 | D9: =Paytable!H6 -> 1.5 | E9: =C9*D9*10 -> 0.012552738 | F9: 0.00083684921
A10: Boilies | B10: 5 | C10: ='Reel Strips'!$H$7*('Reel Strips'!$I$7+'Reel Strips'!$I$18)*('Reel Strips'!$J$7+'Reel Strips'!$J$18)*('Reel Strips'!$K$7+'Reel Strips'!$K$18)*('Reel Strips'!$L$7+'Reel Strips'!$L$18)+'Reel Strips'!$H$18*'Reel Strips'!$I$7*('Reel Strips'!$J$7+'Reel Strips'!$J$18)*('Reel Strips'!$K$7+'Reel Strips'!$K$18)*('Reel Strips'!$L$7+'Reel Strips'!$L$18)+'Reel Strips'!$H$18*'Reel Strips'!$I$18*'Reel Strips'!$J$7*('Reel Strips'!$K$7+'Reel Strips'!$K$18)*('Reel Strips'!$L$7+'Reel Strips'!$L$18)+'Reel Strips'!$H$18*'Reel Strips'!$I$18*'Reel Strips'!$J$18*'Reel Strips'!$K$7*('Reel Strips'!$L$7+'Reel Strips'!$L$18)+'Reel Strips'!$H$18*'Reel Strips'!$I$18*'Reel Strips'!$J$18*'Reel Strips'!$K$18*'Reel Strips'!$L$7 -> 0.00019311905 | D10: =Paytable!I6 -> 3 | E10: =C10*D10*10 -> 0.0057935715 | F10: 0.00019311905
A11: Sweetcorn | B11: 3 | C11: ='Reel Strips'!$H$8*('Reel Strips'!$I$8+'Reel Strips'!$I$18)*('Reel Strips'!$J$8+'Reel Strips'!$J$18)*(1-'Reel Strips'!$K$8-'Reel Strips'!$K$18)+'Reel Strips'!$H$18*'Reel Strips'!$I$8*('Reel Strips'!$J$8+'Reel Strips'!$J$18)*(1-'Reel Strips'!$K$8-'Reel Strips'!$K$18)+'Reel Strips'!$H$18*'Reel Strips'!$I$18*'Reel Strips'!$J$8*(1-'Reel Strips'!$K$8-'Reel Strips'!$K$18) -> 0.0046730042 | D11: =Paytable!G7 -> 0.9 | E11: =C11*D11*10 -> 0.042057037 | F11: 0.0046730042
A12: Sweetcorn | B12: 4 | C12: ='Reel Strips'!$H$8*('Reel Strips'!$I$8+'Reel Strips'!$I$18)*('Reel Strips'!$J$8+'Reel Strips'!$J$18)*('Reel Strips'!$K$8+'Reel Strips'!$K$18)*(1-'Reel Strips'!$L$8-'Reel Strips'!$L$18)+'Reel Strips'!$H$18*'Reel Strips'!$I$8*('Reel Strips'!$J$8+'Reel Strips'!$J$18)*('Reel Strips'!$K$8+'Reel Strips'!$K$18)*(1-'Reel Strips'!$L$8-'Reel Strips'!$L$18)+'Reel Strips'!$H$18*'Reel Strips'!$I$18*'Reel Strips'!$J$8*('Reel Strips'!$K$8+'Reel Strips'!$K$18)*(1-'Reel Strips'!$L$8-'Reel Strips'!$L$18)+'Reel Strips'!$H$18*'Reel Strips'!$I$18*'Reel Strips'!$J$18*'Reel Strips'!$K$8*(1-'Reel Strips'!$L$8-'Reel Strips'!$L$18) -> 0.0010631084 | D12: =Paytable!H7 -> 2.4 | E12: =C12*D12*10 -> 0.025514603 | F12: 0.0010631084
A13: Sweetcorn | B13: 5 | C13: ='Reel Strips'!$H$8*('Reel Strips'!$I$8+'Reel Strips'!$I$18)*('Reel Strips'!$J$8+'Reel Strips'!$J$18)*('Reel Strips'!$K$8+'Reel Strips'!$K$18)*('Reel Strips'!$L$8+'Reel Strips'!$L$18)+'Reel Strips'!$H$18*'Reel Strips'!$I$8*('Reel Strips'!$J$8+'Reel Strips'!$J$18)*('Reel Strips'!$K$8+'Reel Strips'!$K$18)*('Reel Strips'!$L$8+'Reel Strips'!$L$18)+'Reel Strips'!$H$18*'Reel Strips'!$I$18*'Reel Strips'!$J$8*('Reel Strips'!$K$8+'Reel Strips'!$K$18)*('Reel Strips'!$L$8+'Reel Strips'!$L$18)+'Reel Strips'!$H$18*'Reel Strips'!$I$18*'Reel Strips'!$J$18*'Reel Strips'!$K$8*('Reel Strips'!$L$8+'Reel Strips'!$L$18)+'Reel Strips'!$H$18*'Reel Strips'!$I$18*'Reel Strips'!$J$18*'Reel Strips'!$K$18*'Reel Strips'!$L$8 -> 0.00024533272 | D13: =Paytable!I7 -> 4.5 | E13: =C13*D13*10 -> 0.011039972 | F13: 0.00024533272
A14: Pellets | B14: 3 | C14: ='Reel Strips'!$H$9*('Reel Strips'!$I$9+'Reel Strips'!$I$18)*('Reel Strips'!$J$9+'Reel Strips'!$J$18)*(1-'Reel Strips'!$K$9-'Reel Strips'!$K$18)+'Reel Strips'!$H$18*'Reel Strips'!$I$9*('Reel Strips'!$J$9+'Reel Strips'!$J$18)*(1-'Reel Strips'!$K$9-'Reel Strips'!$K$18)+'Reel Strips'!$H$18*'Reel Strips'!$I$18*'Reel Strips'!$J$9*(1-'Reel Strips'!$K$9-'Reel Strips'!$K$18) -> 0.0046730042 | D14: =Paytable!G8 -> 0.9 | E14: =C14*D14*10 -> 0.042057037 | F14: 0.0046730042
A15: Pellets | B15: 4 | C15: ='Reel Strips'!$H$9*('Reel Strips'!$I$9+'Reel Strips'!$I$18)*('Reel Strips'!$J$9+'Reel Strips'!$J$18)*('Reel Strips'!$K$9+'Reel Strips'!$K$18)*(1-'Reel Strips'!$L$9-'Reel Strips'!$L$18)+'Reel Strips'!$H$18*'Reel Strips'!$I$9*('Reel Strips'!$J$9+'Reel Strips'!$J$18)*('Reel Strips'!$K$9+'Reel Strips'!$K$18)*(1-'Reel Strips'!$L$9-'Reel Strips'!$L$18)+'Reel Strips'!$H$18*'Reel Strips'!$I$18*'Reel Strips'!$J$9*('Reel Strips'!$K$9+'Reel Strips'!$K$18)*(1-'Reel Strips'!$L$9-'Reel Strips'!$L$18)+'Reel Strips'!$H$18*'Reel Strips'!$I$18*'Reel Strips'!$J$18*'Reel Strips'!$K$9*(1-'Reel Strips'!$L$9-'Reel Strips'!$L$18) -> 0.0010631084 | D15: =Paytable!H8 -> 2.4 | E15: =C15*D15*10 -> 0.025514603 | F15: 0.0010631084
A16: Pellets | B16: 5 | C16: ='Reel Strips'!$H$9*('Reel Strips'!$I$9+'Reel Strips'!$I$18)*('Reel Strips'!$J$9+'Reel Strips'!$J$18)*('Reel Strips'!$K$9+'Reel Strips'!$K$18)*('Reel Strips'!$L$9+'Reel Strips'!$L$18)+'Reel Strips'!$H$18*'Reel Strips'!$I$9*('Reel Strips'!$J$9+'Reel Strips'!$J$18)*('Reel Strips'!$K$9+'Reel Strips'!$K$18)*('Reel Strips'!$L$9+'Reel Strips'!$L$18)+'Reel Strips'!$H$18*'Reel Strips'!$I$18*'Reel Strips'!$J$9*('Reel Strips'!$K$9+'Reel Strips'!$K$18)*('Reel Strips'!$L$9+'Reel Strips'!$L$18)+'Reel Strips'!$H$18*'Reel Strips'!$I$18*'Reel Strips'!$J$18*'Reel Strips'!$K$9*('Reel Strips'!$L$9+'Reel Strips'!$L$18)+'Reel Strips'!$H$18*'Reel Strips'!$I$18*'Reel Strips'!$J$18*'Reel Strips'!$K$18*'Reel Strips'!$L$9 -> 0.00024533272 | D16: =Paytable!I8 -> 4.5 | E16: =C16*D16*10 -> 0.011039972 | F16: 0.00024533272
A17: Flask | B17: 3 | C17: ='Reel Strips'!$H$10*('Reel Strips'!$I$10+'Reel Strips'!$I$18)*('Reel Strips'!$J$10+'Reel Strips'!$J$18)*(1-'Reel Strips'!$K$10-'Reel Strips'!$K$18)+'Reel Strips'!$H$18*'Reel Strips'!$I$10*('Reel Strips'!$J$10+'Reel Strips'!$J$18)*(1-'Reel Strips'!$K$10-'Reel Strips'!$K$18)+'Reel Strips'!$H$18*'Reel Strips'!$I$18*'Reel Strips'!$J$10*(1-'Reel Strips'!$K$10-'Reel Strips'!$K$18) -> 0.0026779175 | D17: =Paytable!G9 -> 1.2 | E17: =C17*D17*10 -> 0.03213501 | F17: 0.0026779175
A18: Flask | B18: 4 | C18: ='Reel Strips'!$H$10*('Reel Strips'!$I$10+'Reel Strips'!$I$18)*('Reel Strips'!$J$10+'Reel Strips'!$J$18)*('Reel Strips'!$K$10+'Reel Strips'!$K$18)*(1-'Reel Strips'!$L$10-'Reel Strips'!$L$18)+'Reel Strips'!$H$18*'Reel Strips'!$I$10*('Reel Strips'!$J$10+'Reel Strips'!$J$18)*('Reel Strips'!$K$10+'Reel Strips'!$K$18)*(1-'Reel Strips'!$L$10-'Reel Strips'!$L$18)+'Reel Strips'!$H$18*'Reel Strips'!$I$18*'Reel Strips'!$J$10*('Reel Strips'!$K$10+'Reel Strips'!$K$18)*(1-'Reel Strips'!$L$10-'Reel Strips'!$L$18)+'Reel Strips'!$H$18*'Reel Strips'!$I$18*'Reel Strips'!$J$18*'Reel Strips'!$K$10*(1-'Reel Strips'!$L$10-'Reel Strips'!$L$18) -> 0.00052142143 | D18: =Paytable!H9 -> 3 | E18: =C18*D18*10 -> 0.015642643 | F18: 0.00052142143
A19: Flask | B19: 5 | C19: ='Reel Strips'!$H$10*('Reel Strips'!$I$10+'Reel Strips'!$I$18)*('Reel Strips'!$J$10+'Reel Strips'!$J$18)*('Reel Strips'!$K$10+'Reel Strips'!$K$18)*('Reel Strips'!$L$10+'Reel Strips'!$L$18)+'Reel Strips'!$H$18*'Reel Strips'!$I$10*('Reel Strips'!$J$10+'Reel Strips'!$J$18)*('Reel Strips'!$K$10+'Reel Strips'!$K$18)*('Reel Strips'!$L$10+'Reel Strips'!$L$18)+'Reel Strips'!$H$18*'Reel Strips'!$I$18*'Reel Strips'!$J$10*('Reel Strips'!$K$10+'Reel Strips'!$K$18)*('Reel Strips'!$L$10+'Reel Strips'!$L$18)+'Reel Strips'!$H$18*'Reel Strips'!$I$18*'Reel Strips'!$J$18*'Reel Strips'!$K$10*('Reel Strips'!$L$10+'Reel Strips'!$L$18)+'Reel Strips'!$H$18*'Reel Strips'!$I$18*'Reel Strips'!$J$18*'Reel Strips'!$K$18*'Reel Strips'!$L$10 -> 9.6559525e-05 | D19: =Paytable!I9 -> 7.5 | E19: =C19*D19*10 -> 0.0072419643 | F19: 9.6559525e-05
A20: Catapult | B20: 3 | C20: ='Reel Strips'!$H$11*('Reel Strips'!$I$11+'Reel Strips'!$I$18)*('Reel Strips'!$J$11+'Reel Strips'!$J$18)*(1-'Reel Strips'!$K$11-'Reel Strips'!$K$18)+'Reel Strips'!$H$18*'Reel Strips'!$I$11*('Reel Strips'!$J$11+'Reel Strips'!$J$18)*(1-'Reel Strips'!$K$11-'Reel Strips'!$K$18)+'Reel Strips'!$H$18*'Reel Strips'!$I$18*'Reel Strips'!$J$11*(1-'Reel Strips'!$K$11-'Reel Strips'!$K$18) -> 0.0019311905 | D20: =Paytable!G10 -> 1.5 | E20: =C20*D20*10 -> 0.028967857 | F20: 0.0019311905
A21: Catapult | B21: 4 | C21: ='Reel Strips'!$H$11*('Reel Strips'!$I$11+'Reel Strips'!$I$18)*('Reel Strips'!$J$11+'Reel Strips'!$J$18)*('Reel Strips'!$K$11+'Reel Strips'!$K$18)*(1-'Reel Strips'!$L$11-'Reel Strips'!$L$18)+'Reel Strips'!$H$18*'Reel Strips'!$I$11*('Reel Strips'!$J$11+'Reel Strips'!$J$18)*('Reel Strips'!$K$11+'Reel Strips'!$K$18)*(1-'Reel Strips'!$L$11-'Reel Strips'!$L$18)+'Reel Strips'!$H$18*'Reel Strips'!$I$18*'Reel Strips'!$J$11*('Reel Strips'!$K$11+'Reel Strips'!$K$18)*(1-'Reel Strips'!$L$11-'Reel Strips'!$L$18)+'Reel Strips'!$H$18*'Reel Strips'!$I$18*'Reel Strips'!$J$18*'Reel Strips'!$K$11*(1-'Reel Strips'!$L$11-'Reel Strips'!$L$18) -> 0.00030174851 | D21: =Paytable!H10 -> 3.6 | E21: =C21*D21*10 -> 0.010862947 | F21: 0.00030174851
A22: Catapult | B22: 5 | C22: ='Reel Strips'!$H$11*('Reel Strips'!$I$11+'Reel Strips'!$I$18)*('Reel Strips'!$J$11+'Reel Strips'!$J$18)*('Reel Strips'!$K$11+'Reel Strips'!$K$18)*('Reel Strips'!$L$11+'Reel Strips'!$L$18)+'Reel Strips'!$H$18*'Reel Strips'!$I$11*('Reel Strips'!$J$11+'Reel Strips'!$J$18)*('Reel Strips'!$K$11+'Reel Strips'!$K$18)*('Reel Strips'!$L$11+'Reel Strips'!$L$18)+'Reel Strips'!$H$18*'Reel Strips'!$I$18*'Reel Strips'!$J$11*('Reel Strips'!$K$11+'Reel Strips'!$K$18)*('Reel Strips'!$L$11+'Reel Strips'!$L$18)+'Reel Strips'!$H$18*'Reel Strips'!$I$18*'Reel Strips'!$J$18*'Reel Strips'!$K$11*('Reel Strips'!$L$11+'Reel Strips'!$L$18)+'Reel Strips'!$H$18*'Reel Strips'!$I$18*'Reel Strips'!$J$18*'Reel Strips'!$K$18*'Reel Strips'!$L$11 -> 5.5879354e-05 | D22: =Paytable!I10 -> 9 | E22: =C22*D22*10 -> 0.0050291419 | F22: 5.5879354e-05
A23: Landing Net | B23: 3 | C23: ='Reel Strips'!$H$12*('Reel Strips'!$I$12+'Reel Strips'!$I$18)*('Reel Strips'!$J$12+'Reel Strips'!$J$18)*(1-'Reel Strips'!$K$12-'Reel Strips'!$K$18)+'Reel Strips'!$H$18*'Reel Strips'!$I$12*('Reel Strips'!$J$12+'Reel Strips'!$J$18)*(1-'Reel Strips'!$K$12-'Reel Strips'!$K$18)+'Reel Strips'!$H$18*'Reel Strips'!$I$18*'Reel Strips'!$J$12*(1-'Reel Strips'!$K$12-'Reel Strips'!$K$18) -> 0.0012874603 | D23: =Paytable!G11 -> 1.8 | E23: =C23*D23*10 -> 0.023174286 | F23: 0.0012874603
A24: Landing Net | B24: 4 | C24: ='Reel Strips'!$H$12*('Reel Strips'!$I$12+'Reel Strips'!$I$18)*('Reel Strips'!$J$12+'Reel Strips'!$J$18)*('Reel Strips'!$K$12+'Reel Strips'!$K$18)*(1-'Reel Strips'!$L$12-'Reel Strips'!$L$18)+'Reel Strips'!$H$18*'Reel Strips'!$I$12*('Reel Strips'!$J$12+'Reel Strips'!$J$18)*('Reel Strips'!$K$12+'Reel Strips'!$K$18)*(1-'Reel Strips'!$L$12-'Reel Strips'!$L$18)+'Reel Strips'!$H$18*'Reel Strips'!$I$18*'Reel Strips'!$J$12*('Reel Strips'!$K$12+'Reel Strips'!$K$18)*(1-'Reel Strips'!$L$12-'Reel Strips'!$L$18)+'Reel Strips'!$H$18*'Reel Strips'!$I$18*'Reel Strips'!$J$18*'Reel Strips'!$K$12*(1-'Reel Strips'!$L$12-'Reel Strips'!$L$18) -> 0.00020861626 | D24: =Paytable!H11 -> 4.5 | E24: =C24*D24*10 -> 0.0093877316 | F24: 0.00020861626
A25: Landing Net | B25: 5 | C25: ='Reel Strips'!$H$12*('Reel Strips'!$I$12+'Reel Strips'!$I$18)*('Reel Strips'!$J$12+'Reel Strips'!$J$18)*('Reel Strips'!$K$12+'Reel Strips'!$K$18)*('Reel Strips'!$L$12+'Reel Strips'!$L$18)+'Reel Strips'!$H$18*'Reel Strips'!$I$12*('Reel Strips'!$J$12+'Reel Strips'!$J$18)*('Reel Strips'!$K$12+'Reel Strips'!$K$18)*('Reel Strips'!$L$12+'Reel Strips'!$L$18)+'Reel Strips'!$H$18*'Reel Strips'!$I$18*'Reel Strips'!$J$12*('Reel Strips'!$K$12+'Reel Strips'!$K$18)*('Reel Strips'!$L$12+'Reel Strips'!$L$18)+'Reel Strips'!$H$18*'Reel Strips'!$I$18*'Reel Strips'!$J$18*'Reel Strips'!$K$12*('Reel Strips'!$L$12+'Reel Strips'!$L$18)+'Reel Strips'!$H$18*'Reel Strips'!$I$18*'Reel Strips'!$J$18*'Reel Strips'!$K$18*'Reel Strips'!$L$12 -> 2.9802322e-05 | D25: =Paytable!I11 -> 12 | E25: =C25*D25*10 -> 0.0035762787 | F25: 2.9802322e-05
A26: Bivvy | B26: 3 | C26: ='Reel Strips'!$H$13*('Reel Strips'!$I$13+'Reel Strips'!$I$18)*('Reel Strips'!$J$13+'Reel Strips'!$J$18)*(1-'Reel Strips'!$K$13-'Reel Strips'!$K$18)+'Reel Strips'!$H$18*'Reel Strips'!$I$13*('Reel Strips'!$J$13+'Reel Strips'!$J$18)*(1-'Reel Strips'!$K$13-'Reel Strips'!$K$18)+'Reel Strips'!$H$18*'Reel Strips'!$I$18*'Reel Strips'!$J$13*(1-'Reel Strips'!$K$13-'Reel Strips'!$K$18) -> 0.0012874603 | D26: =Paytable!G12 -> 2.4 | E26: =C26*D26*10 -> 0.030899048 | F26: 0.0012874603
A27: Bivvy | B27: 4 | C27: ='Reel Strips'!$H$13*('Reel Strips'!$I$13+'Reel Strips'!$I$18)*('Reel Strips'!$J$13+'Reel Strips'!$J$18)*('Reel Strips'!$K$13+'Reel Strips'!$K$18)*(1-'Reel Strips'!$L$13-'Reel Strips'!$L$18)+'Reel Strips'!$H$18*'Reel Strips'!$I$13*('Reel Strips'!$J$13+'Reel Strips'!$J$18)*('Reel Strips'!$K$13+'Reel Strips'!$K$18)*(1-'Reel Strips'!$L$13-'Reel Strips'!$L$18)+'Reel Strips'!$H$18*'Reel Strips'!$I$18*'Reel Strips'!$J$13*('Reel Strips'!$K$13+'Reel Strips'!$K$18)*(1-'Reel Strips'!$L$13-'Reel Strips'!$L$18)+'Reel Strips'!$H$18*'Reel Strips'!$I$18*'Reel Strips'!$J$18*'Reel Strips'!$K$13*(1-'Reel Strips'!$L$13-'Reel Strips'!$L$18) -> 0.00020861626 | D27: =Paytable!H12 -> 6 | E27: =C27*D27*10 -> 0.012516975 | F27: 0.00020861626
A28: Bivvy | B28: 5 | C28: ='Reel Strips'!$H$13*('Reel Strips'!$I$13+'Reel Strips'!$I$18)*('Reel Strips'!$J$13+'Reel Strips'!$J$18)*('Reel Strips'!$K$13+'Reel Strips'!$K$18)*('Reel Strips'!$L$13+'Reel Strips'!$L$18)+'Reel Strips'!$H$18*'Reel Strips'!$I$13*('Reel Strips'!$J$13+'Reel Strips'!$J$18)*('Reel Strips'!$K$13+'Reel Strips'!$K$18)*('Reel Strips'!$L$13+'Reel Strips'!$L$18)+'Reel Strips'!$H$18*'Reel Strips'!$I$18*'Reel Strips'!$J$13*('Reel Strips'!$K$13+'Reel Strips'!$K$18)*('Reel Strips'!$L$13+'Reel Strips'!$L$18)+'Reel Strips'!$H$18*'Reel Strips'!$I$18*'Reel Strips'!$J$18*'Reel Strips'!$K$13*('Reel Strips'!$L$13+'Reel Strips'!$L$18)+'Reel Strips'!$H$18*'Reel Strips'!$I$18*'Reel Strips'!$J$18*'Reel Strips'!$K$18*'Reel Strips'!$L$13 -> 2.9802322e-05 | D28: =Paytable!I12 -> 15 | E28: =C28*D28*10 -> 0.0044703484 | F28: 2.9802322e-05
A29: Roach | B29: 3 | C29: ='Reel Strips'!$H$14*('Reel Strips'!$I$14+'Reel Strips'!$I$18)*('Reel Strips'!$J$14+'Reel Strips'!$J$18)*(1-'Reel Strips'!$K$14-'Reel Strips'!$K$18)+'Reel Strips'!$H$18*'Reel Strips'!$I$14*('Reel Strips'!$J$14+'Reel Strips'!$J$18)*(1-'Reel Strips'!$K$14-'Reel Strips'!$K$18)+'Reel Strips'!$H$18*'Reel Strips'!$I$18*'Reel Strips'!$J$14*(1-'Reel Strips'!$K$14-'Reel Strips'!$K$18) -> 0.00042724609 | D29: =Paytable!G13 -> 3 | E29: =C29*D29*10 -> 0.012817383 | F29: 0.00042724609
A30: Roach | B30: 4 | C30: ='Reel Strips'!$H$14*('Reel Strips'!$I$14+'Reel Strips'!$I$18)*('Reel Strips'!$J$14+'Reel Strips'!$J$18)*('Reel Strips'!$K$14+'Reel Strips'!$K$18)*(1-'Reel Strips'!$L$14-'Reel Strips'!$L$18)+'Reel Strips'!$H$18*'Reel Strips'!$I$14*('Reel Strips'!$J$14+'Reel Strips'!$J$18)*('Reel Strips'!$K$14+'Reel Strips'!$K$18)*(1-'Reel Strips'!$L$14-'Reel Strips'!$L$18)+'Reel Strips'!$H$18*'Reel Strips'!$I$18*'Reel Strips'!$J$14*('Reel Strips'!$K$14+'Reel Strips'!$K$18)*(1-'Reel Strips'!$L$14-'Reel Strips'!$L$18)+'Reel Strips'!$H$18*'Reel Strips'!$I$18*'Reel Strips'!$J$18*'Reel Strips'!$K$14*(1-'Reel Strips'!$L$14-'Reel Strips'!$L$18) -> 5.531311e-05 | D30: =Paytable!H13 -> 7.5 | E30: =C30*D30*10 -> 0.0041484833 | F30: 5.531311e-05
A31: Roach | B31: 5 | C31: ='Reel Strips'!$H$14*('Reel Strips'!$I$14+'Reel Strips'!$I$18)*('Reel Strips'!$J$14+'Reel Strips'!$J$18)*('Reel Strips'!$K$14+'Reel Strips'!$K$18)*('Reel Strips'!$L$14+'Reel Strips'!$L$18)+'Reel Strips'!$H$18*'Reel Strips'!$I$14*('Reel Strips'!$J$14+'Reel Strips'!$J$18)*('Reel Strips'!$K$14+'Reel Strips'!$K$18)*('Reel Strips'!$L$14+'Reel Strips'!$L$18)+'Reel Strips'!$H$18*'Reel Strips'!$I$18*'Reel Strips'!$J$14*('Reel Strips'!$K$14+'Reel Strips'!$K$18)*('Reel Strips'!$L$14+'Reel Strips'!$L$18)+'Reel Strips'!$H$18*'Reel Strips'!$I$18*'Reel Strips'!$J$18*'Reel Strips'!$K$14*('Reel Strips'!$L$14+'Reel Strips'!$L$18)+'Reel Strips'!$H$18*'Reel Strips'!$I$18*'Reel Strips'!$J$18*'Reel Strips'!$K$18*'Reel Strips'!$L$14 -> 5.7220459e-06 | D31: =Paytable!I13 -> 18 | E31: =C31*D31*10 -> 0.0010299683 | F31: 5.7220459e-06
A32: Bream | B32: 3 | C32: ='Reel Strips'!$H$15*('Reel Strips'!$I$15+'Reel Strips'!$I$18)*('Reel Strips'!$J$15+'Reel Strips'!$J$18)*(1-'Reel Strips'!$K$15-'Reel Strips'!$K$18)+'Reel Strips'!$H$18*'Reel Strips'!$I$15*('Reel Strips'!$J$15+'Reel Strips'!$J$18)*(1-'Reel Strips'!$K$15-'Reel Strips'!$K$18)+'Reel Strips'!$H$18*'Reel Strips'!$I$18*'Reel Strips'!$J$15*(1-'Reel Strips'!$K$15-'Reel Strips'!$K$18) -> 0.00042724609 | D32: =Paytable!G14 -> 3.6 | E32: =C32*D32*10 -> 0.015380859 | F32: 0.00042724609
A33: Bream | B33: 4 | C33: ='Reel Strips'!$H$15*('Reel Strips'!$I$15+'Reel Strips'!$I$18)*('Reel Strips'!$J$15+'Reel Strips'!$J$18)*('Reel Strips'!$K$15+'Reel Strips'!$K$18)*(1-'Reel Strips'!$L$15-'Reel Strips'!$L$18)+'Reel Strips'!$H$18*'Reel Strips'!$I$15*('Reel Strips'!$J$15+'Reel Strips'!$J$18)*('Reel Strips'!$K$15+'Reel Strips'!$K$18)*(1-'Reel Strips'!$L$15-'Reel Strips'!$L$18)+'Reel Strips'!$H$18*'Reel Strips'!$I$18*'Reel Strips'!$J$15*('Reel Strips'!$K$15+'Reel Strips'!$K$18)*(1-'Reel Strips'!$L$15-'Reel Strips'!$L$18)+'Reel Strips'!$H$18*'Reel Strips'!$I$18*'Reel Strips'!$J$18*'Reel Strips'!$K$15*(1-'Reel Strips'!$L$15-'Reel Strips'!$L$18) -> 5.531311e-05 | D33: =Paytable!H14 -> 9 | E33: =C33*D33*10 -> 0.0049781799 | F33: 5.531311e-05
A34: Bream | B34: 5 | C34: ='Reel Strips'!$H$15*('Reel Strips'!$I$15+'Reel Strips'!$I$18)*('Reel Strips'!$J$15+'Reel Strips'!$J$18)*('Reel Strips'!$K$15+'Reel Strips'!$K$18)*('Reel Strips'!$L$15+'Reel Strips'!$L$18)+'Reel Strips'!$H$18*'Reel Strips'!$I$15*('Reel Strips'!$J$15+'Reel Strips'!$J$18)*('Reel Strips'!$K$15+'Reel Strips'!$K$18)*('Reel Strips'!$L$15+'Reel Strips'!$L$18)+'Reel Strips'!$H$18*'Reel Strips'!$I$18*'Reel Strips'!$J$15*('Reel Strips'!$K$15+'Reel Strips'!$K$18)*('Reel Strips'!$L$15+'Reel Strips'!$L$18)+'Reel Strips'!$H$18*'Reel Strips'!$I$18*'Reel Strips'!$J$18*'Reel Strips'!$K$15*('Reel Strips'!$L$15+'Reel Strips'!$L$18)+'Reel Strips'!$H$18*'Reel Strips'!$I$18*'Reel Strips'!$J$18*'Reel Strips'!$K$18*'Reel Strips'!$L$15 -> 5.7220459e-06 | D34: =Paytable!I14 -> 24 | E34: =C34*D34*10 -> 0.001373291 | F34: 5.7220459e-06
A35: Tench | B35: 3 | C35: ='Reel Strips'!$H$16*('Reel Strips'!$I$16+'Reel Strips'!$I$18)*('Reel Strips'!$J$16+'Reel Strips'!$J$18)*(1-'Reel Strips'!$K$16-'Reel Strips'!$K$18)+'Reel Strips'!$H$18*'Reel Strips'!$I$16*('Reel Strips'!$J$16+'Reel Strips'!$J$18)*(1-'Reel Strips'!$K$16-'Reel Strips'!$K$18)+'Reel Strips'!$H$18*'Reel Strips'!$I$18*'Reel Strips'!$J$16*(1-'Reel Strips'!$K$16-'Reel Strips'!$K$18) -> 0.00042724609 | D35: =Paytable!G15 -> 4.5 | E35: =C35*D35*10 -> 0.019226074 | F35: 0.00042724609
A36: Tench | B36: 4 | C36: ='Reel Strips'!$H$16*('Reel Strips'!$I$16+'Reel Strips'!$I$18)*('Reel Strips'!$J$16+'Reel Strips'!$J$18)*('Reel Strips'!$K$16+'Reel Strips'!$K$18)*(1-'Reel Strips'!$L$16-'Reel Strips'!$L$18)+'Reel Strips'!$H$18*'Reel Strips'!$I$16*('Reel Strips'!$J$16+'Reel Strips'!$J$18)*('Reel Strips'!$K$16+'Reel Strips'!$K$18)*(1-'Reel Strips'!$L$16-'Reel Strips'!$L$18)+'Reel Strips'!$H$18*'Reel Strips'!$I$18*'Reel Strips'!$J$16*('Reel Strips'!$K$16+'Reel Strips'!$K$18)*(1-'Reel Strips'!$L$16-'Reel Strips'!$L$18)+'Reel Strips'!$H$18*'Reel Strips'!$I$18*'Reel Strips'!$J$18*'Reel Strips'!$K$16*(1-'Reel Strips'!$L$16-'Reel Strips'!$L$18) -> 5.531311e-05 | D36: =Paytable!H15 -> 12 | E36: =C36*D36*10 -> 0.0066375732 | F36: 5.531311e-05
A37: Tench | B37: 5 | C37: ='Reel Strips'!$H$16*('Reel Strips'!$I$16+'Reel Strips'!$I$18)*('Reel Strips'!$J$16+'Reel Strips'!$J$18)*('Reel Strips'!$K$16+'Reel Strips'!$K$18)*('Reel Strips'!$L$16+'Reel Strips'!$L$18)+'Reel Strips'!$H$18*'Reel Strips'!$I$16*('Reel Strips'!$J$16+'Reel Strips'!$J$18)*('Reel Strips'!$K$16+'Reel Strips'!$K$18)*('Reel Strips'!$L$16+'Reel Strips'!$L$18)+'Reel Strips'!$H$18*'Reel Strips'!$I$18*'Reel Strips'!$J$16*('Reel Strips'!$K$16+'Reel Strips'!$K$18)*('Reel Strips'!$L$16+'Reel Strips'!$L$18)+'Reel Strips'!$H$18*'Reel Strips'!$I$18*'Reel Strips'!$J$18*'Reel Strips'!$K$16*('Reel Strips'!$L$16+'Reel Strips'!$L$18)+'Reel Strips'!$H$18*'Reel Strips'!$I$18*'Reel Strips'!$J$18*'Reel Strips'!$K$18*'Reel Strips'!$L$16 -> 5.7220459e-06 | D37: =Paytable!I15 -> 36 | E37: =C37*D37*10 -> 0.0020599365 | F37: 5.7220459e-06
A38: Mirror Carp | B38: 3 | C38: ='Reel Strips'!$H$17*('Reel Strips'!$I$17+'Reel Strips'!$I$18)*('Reel Strips'!$J$17+'Reel Strips'!$J$18)*(1-'Reel Strips'!$K$17-'Reel Strips'!$K$18)+'Reel Strips'!$H$18*'Reel Strips'!$I$17*('Reel Strips'!$J$17+'Reel Strips'!$J$18)*(1-'Reel Strips'!$K$17-'Reel Strips'!$K$18)+'Reel Strips'!$H$18*'Reel Strips'!$I$18*'Reel Strips'!$J$17*(1-'Reel Strips'!$K$17-'Reel Strips'!$K$18) -> 0.00042724609 | D38: =Paytable!G16 -> 6 | E38: =C38*D38*10 -> 0.025634766 | F38: 0.00042724609
A39: Mirror Carp | B39: 4 | C39: ='Reel Strips'!$H$17*('Reel Strips'!$I$17+'Reel Strips'!$I$18)*('Reel Strips'!$J$17+'Reel Strips'!$J$18)*('Reel Strips'!$K$17+'Reel Strips'!$K$18)*(1-'Reel Strips'!$L$17-'Reel Strips'!$L$18)+'Reel Strips'!$H$18*'Reel Strips'!$I$17*('Reel Strips'!$J$17+'Reel Strips'!$J$18)*('Reel Strips'!$K$17+'Reel Strips'!$K$18)*(1-'Reel Strips'!$L$17-'Reel Strips'!$L$18)+'Reel Strips'!$H$18*'Reel Strips'!$I$18*'Reel Strips'!$J$17*('Reel Strips'!$K$17+'Reel Strips'!$K$18)*(1-'Reel Strips'!$L$17-'Reel Strips'!$L$18)+'Reel Strips'!$H$18*'Reel Strips'!$I$18*'Reel Strips'!$J$18*'Reel Strips'!$K$17*(1-'Reel Strips'!$L$17-'Reel Strips'!$L$18) -> 5.531311e-05 | D39: =Paytable!H16 -> 22.5 | E39: =C39*D39*10 -> 0.01244545 | F39: 5.531311e-05
A40: Mirror Carp | B40: 5 | C40: ='Reel Strips'!$H$17*('Reel Strips'!$I$17+'Reel Strips'!$I$18)*('Reel Strips'!$J$17+'Reel Strips'!$J$18)*('Reel Strips'!$K$17+'Reel Strips'!$K$18)*('Reel Strips'!$L$17+'Reel Strips'!$L$18)+'Reel Strips'!$H$18*'Reel Strips'!$I$17*('Reel Strips'!$J$17+'Reel Strips'!$J$18)*('Reel Strips'!$K$17+'Reel Strips'!$K$18)*('Reel Strips'!$L$17+'Reel Strips'!$L$18)+'Reel Strips'!$H$18*'Reel Strips'!$I$18*'Reel Strips'!$J$17*('Reel Strips'!$K$17+'Reel Strips'!$K$18)*('Reel Strips'!$L$17+'Reel Strips'!$L$18)+'Reel Strips'!$H$18*'Reel Strips'!$I$18*'Reel Strips'!$J$18*'Reel Strips'!$K$17*('Reel Strips'!$L$17+'Reel Strips'!$L$18)+'Reel Strips'!$H$18*'Reel Strips'!$I$18*'Reel Strips'!$J$18*'Reel Strips'!$K$18*'Reel Strips'!$L$17+'Reel Strips'!$H$18*'Reel Strips'!$I$18*'Reel Strips'!$J$18*'Reel Strips'!$K$18*'Reel Strips'!$L$18 -> 5.7220459e-06 | D40: =Paytable!I16 -> 75 | E40: =C40*D40*10 -> 0.0042915344 | F40: 5.7220459e-06
A41: Total line RTP | E41: =SUM(E5:E40) -> 0.54140192
...

Sheet Line Wins Free Spins
A1: Line Wins Free Spins: exact probability per payline
A2: Formula: the first non-wild symbol on the line is the target; wilds before/after it count; the next symbol must break the run. Probabilities come from Reel Strips; RTP contribution = probability x pay (x stake) x 10 lines.
A4: Symbol | B4: Count | C4: P (per line) | D4: Pay (x stake) | E4: RTP contribution | F4: Check: engine exact
A5: Float | B5: 3 | C5: ='Reel Strips'!$H$25*('Reel Strips'!$I$25+'Reel Strips'!$I$37)*('Reel Strips'!$J$25+'Reel Strips'!$J$37)*(1-'Reel Strips'!$K$25-'Reel Strips'!$K$37)+'Reel Strips'!$H$37*'Reel Strips'!$I$25*('Reel Strips'!$J$25+'Reel Strips'!$J$37)*(1-'Reel Strips'!$K$25-'Reel Strips'!$K$37)+'Reel Strips'!$H$37*'Reel Strips'!$I$37*'Reel Strips'!$J$25*(1-'Reel Strips'!$K$25-'Reel Strips'!$K$37) -> 0.0019311905 | D5: =Paytable!G5 -> 0.6 | E5: =C5*D5*10 -> 0.011587143 | F5: 0.0019311905
A6: Float | B6: 4 | C6: ='Reel Strips'!$H$25*('Reel Strips'!$I$25+'Reel Strips'!$I$37)*('Reel Strips'!$J$25+'Reel Strips'!$J$37)*('Reel Strips'!$K$25+'Reel Strips'!$K$37)*(1-'Reel Strips'!$L$25-'Reel Strips'!$L$37)+'Reel Strips'!$H$37*'Reel Strips'!$I$25*('Reel Strips'!$J$25+'Reel Strips'!$J$37)*('Reel Strips'!$K$25+'Reel Strips'!$K$37)*(1-'Reel Strips'!$L$25-'Reel Strips'!$L$37)+'Reel Strips'!$H$37*'Reel Strips'!$I$37*'Reel Strips'!$J$25*('Reel Strips'!$K$25+'Reel Strips'!$K$37)*(1-'Reel Strips'!$L$25-'Reel Strips'!$L$37)+'Reel Strips'!$H$37*'Reel Strips'!$I$37*'Reel Strips'!$J$37*'Reel Strips'!$K$25*(1-'Reel Strips'!$L$25-'Reel Strips'!$L$37) -> 0.00030174851 | D6: =Paytable!H5 -> 1.5 | E6: =C6*D6*10 -> 0.0045262277 | F6: 0.00030174851
A7: Float | B7: 5 | C7: ='Reel Strips'!$H$25*('Reel Strips'!$I$25+'Reel Strips'!$I$37)*('Reel Strips'!$J$25+'Reel Strips'!$J$37)*('Reel Strips'!$K$25+'Reel Strips'!$K$37)*('Reel Strips'!$L$25+'Reel Strips'!$L$37)+'Reel Strips'!$H$37*'Reel Strips'!$I$25*('Reel Strips'!$J$25+'Reel Strips'!$J$37)*('Reel Strips'!$K$25+'Reel Strips'!$K$37)*('Reel Strips'!$L$25+'Reel Strips'!$L$37)+'Reel Strips'!$H$37*'Reel Strips'!$I$37*'Reel Strips'!$J$25*('Reel Strips'!$K$25+'Reel Strips'!$K$37)*('Reel Strips'!$L$25+'Reel Strips'!$L$37)+'Reel Strips'!$H$37*'Reel Strips'!$I$37*'Reel Strips'!$J$37*'Reel Strips'!$K$25*('Reel Strips'!$L$25+'Reel Strips'!$L$37)+'Reel Strips'!$H$37*'Reel Strips'!$I$37*'Reel Strips'!$J$37*'Reel Strips'!$K$37*'Reel Strips'!$L$25 -> 5.5879354e-05 | D7: =Paytable!I5 -> 3 | E7: =C7*D7*10 -> 0.0016763806 | F7: 5.5879354e-05
A8: Boilies | B8: 3 | C8: ='Reel Strips'!$H$26*('Reel Strips'!$I$26+'Reel Strips'!$I$37)*('Reel Strips'!$J$26+'Reel Strips'!$J$37)*(1-'Reel Strips'!$K$26-'Reel Strips'!$K$37)+'Reel Strips'!$H$37*'Reel Strips'!$I$26*('Reel Strips'!$J$26+'Reel Strips'!$J$37)*(1-'Reel Strips'!$K$26-'Reel Strips'!$K$37)+'Reel Strips'!$H$37*'Reel Strips'!$I$37*'Reel Strips'!$J$26*(1-'Reel Strips'!$K$26-'Reel Strips'!$K$37) -> 0.0019311905 | D8: =Paytable!G6 -> 0.6 | E8: =C8*D8*10 -> 0.011587143 | F8: 0.0019311905
A9: Boilies | B9: 4 | C9: ='Reel Strips'!$H$26*('Reel Strips'!$I$26+'Reel Strips'!$I$37)*('Reel Strips'!$J$26+'Reel Strips'!$J$37)*('Reel Strips'!$K$26+'Reel Strips'!$K$37)*(1-'Reel Strips'!$L$26-'Reel Strips'!$L$37)+'Reel Strips'!$H$37*'Reel Strips'!$I$26*('Reel Strips'!$J$26+'Reel Strips'!$J$37)*('Reel Strips'!$K$26+'Reel Strips'!$K$37)*(1-'Reel Strips'!$L$26-'Reel Strips'!$L$37)+'Reel Strips'!$H$37*'Reel Strips'!$I$37*'Reel Strips'!$J$26*('Reel Strips'!$K$26+'Reel Strips'!$K$37)*(1-'Reel Strips'!$L$26-'Reel Strips'!$L$37)+'Reel Strips'!$H$37*'Reel Strips'!$I$37*'Reel Strips'!$J$37*'Reel Strips'!$K$26*(1-'Reel Strips'!$L$26-'Reel Strips'!$L$37) -> 0.00030174851 | D9: =Paytable!H6 -> 1.5 | E9: =C9*D9*10 -> 0.0045262277 | F9: 0.00030174851
A10: Boilies | B10: 5 | C10: ='Reel Strips'!$H$26*('Reel Strips'!$I$26+'Reel Strips'!$I$37)*('Reel Strips'!$J$26+'Reel Strips'!$J$37)*('Reel Strips'!$K$26+'Reel Strips'!$K$37)*('Reel Strips'!$L$26+'Reel Strips'!$L$37)+'Reel Strips'!$H$37*'Reel Strips'!$I$26*('Reel Strips'!$J$26+'Reel Strips'!$J$37)*('Reel Strips'!$K$26+'Reel Strips'!$K$37)*('Reel Strips'!$L$26+'Reel Strips'!$L$37)+'Reel Strips'!$H$37*'Reel Strips'!$I$37*'Reel Strips'!$J$26*('Reel Strips'!$K$26+'Reel Strips'!$K$37)*('Reel Strips'!$L$26+'Reel Strips'!$L$37)+'Reel Strips'!$H$37*'Reel Strips'!$I$37*'Reel Strips'!$J$37*'Reel Strips'!$K$26*('Reel Strips'!$L$26+'Reel Strips'!$L$37)+'Reel Strips'!$H$37*'Reel Strips'!$I$37*'Reel Strips'!$J$37*'Reel Strips'!$K$37*'Reel Strips'!$L$26 -> 5.5879354e-05 | D10: =Paytable!I6 -> 3 | E10: =C10*D10*10 -> 0.0016763806 | F10: 5.5879354e-05
A11: Sweetcorn | B11: 3 | C11: ='Reel Strips'!$H$27*('Reel Strips'!$I$27+'Reel Strips'!$I$37)*('Reel Strips'!$J$27+'Reel Strips'!$J$37)*(1-'Reel Strips'!$K$27-'Reel Strips'!$K$37)+'Reel Strips'!$H$37*'Reel Strips'!$I$27*('Reel Strips'!$J$27+'Reel Strips'!$J$37)*(1-'Reel Strips'!$K$27-'Reel Strips'!$K$37)+'Reel Strips'!$H$37*'Reel Strips'!$I$37*'Reel Strips'!$J$27*(1-'Reel Strips'!$K$27-'Reel Strips'!$K$37) -> 0.0035705566 | D11: =Paytable!G7 -> 0.9 | E11: =C11*D11*10 -> 0.03213501 | F11: 0.0035705566
A12: Sweetcorn | B12: 4 | C12: ='Reel Strips'!$H$27*('Reel Strips'!$I$27+'Reel Strips'!$I$37)*('Reel Strips'!$J$27+'Reel Strips'!$J$37)*('Reel Strips'!$K$27+'Reel Strips'!$K$37)*(1-'Reel Strips'!$L$27-'Reel Strips'!$L$37)+'Reel Strips'!$H$37*'Reel Strips'!$I$27*('Reel Strips'!$J$27+'Reel Strips'!$J$37)*('Reel Strips'!$K$27+'Reel Strips'!$K$37)*(1-'Reel Strips'!$L$27-'Reel Strips'!$L$37)+'Reel Strips'!$H$37*'Reel Strips'!$I$37*'Reel Strips'!$J$27*('Reel Strips'!$K$27+'Reel Strips'!$K$37)*(1-'Reel Strips'!$L$27-'Reel Strips'!$L$37)+'Reel Strips'!$H$37*'Reel Strips'!$I$37*'Reel Strips'!$J$37*'Reel Strips'!$K$27*(1-'Reel Strips'!$L$27-'Reel Strips'!$L$37) -> 0.00069522858 | D12: =Paytable!H7 -> 2.4 | E12: =C12*D12*10 -> 0.016685486 | F12: 0.00069522858
A13: Sweetcorn | B13: 5 | C13: ='Reel Strips'!$H$27*('Reel Strips'!$I$27+'Reel Strips'!$I$37)*('Reel Strips'!$J$27+'Reel Strips'!$J$37)*('Reel Strips'!$K$27+'Reel Strips'!$K$37)*('Reel Strips'!$L$27+'Reel Strips'!$L$37)+'Reel Strips'!$H$37*'Reel Strips'!$I$27*('Reel Strips'!$J$27+'Reel Strips'!$J$37)*('Reel Strips'!$K$27+'Reel Strips'!$K$37)*('Reel Strips'!$L$27+'Reel Strips'!$L$37)+'Reel Strips'!$H$37*'Reel Strips'!$I$37*'Reel Strips'!$J$27*('Reel Strips'!$K$27+'Reel Strips'!$K$37)*('Reel Strips'!$L$27+'Reel Strips'!$L$37)+'Reel Strips'!$H$37*'Reel Strips'!$I$37*'Reel Strips'!$J$37*'Reel Strips'!$K$27*('Reel Strips'!$L$27+'Reel Strips'!$L$37)+'Reel Strips'!$H$37*'Reel Strips'!$I$37*'Reel Strips'!$J$37*'Reel Strips'!$K$37*'Reel Strips'!$L$27 -> 0.00012874603 | D13: =Paytable!I7 -> 4.5 | E13: =C13*D13*10 -> 0.0057935715 | F13: 0.00012874603
A14: Pellets | B14: 3 | C14: ='Reel Strips'!$H$28*('Reel Strips'!$I$28+'Reel Strips'!$I$37)*('Reel Strips'!$J$28+'Reel Strips'!$J$37)*(1-'Reel Strips'!$K$28-'Reel Strips'!$K$37)+'Reel Strips'!$H$37*'Reel Strips'!$I$28*('Reel Strips'!$J$28+'Reel Strips'!$J$37)*(1-'Reel Strips'!$K$28-'Reel Strips'!$K$37)+'Reel Strips'!$H$37*'Reel Strips'!$I$37*'Reel Strips'!$J$28*(1-'Reel Strips'!$K$28-'Reel Strips'!$K$37) -> 0.0035705566 | D14: =Paytable!G8 -> 0.9 | E14: =C14*D14*10 -> 0.03213501 | F14: 0.0035705566
A15: Pellets | B15: 4 | C15: ='Reel Strips'!$H$28*('Reel Strips'!$I$28+'Reel Strips'!$I$37)*('Reel Strips'!$J$28+'Reel Strips'!$J$37)*('Reel Strips'!$K$28+'Reel Strips'!$K$37)*(1-'Reel Strips'!$L$28-'Reel Strips'!$L$37)+'Reel Strips'!$H$37*'Reel Strips'!$I$28*('Reel Strips'!$J$28+'Reel Strips'!$J$37)*('Reel Strips'!$K$28+'Reel Strips'!$K$37)*(1-'Reel Strips'!$L$28-'Reel Strips'!$L$37)+'Reel Strips'!$H$37*'Reel Strips'!$I$37*'Reel Strips'!$J$28*('Reel Strips'!$K$28+'Reel Strips'!$K$37)*(1-'Reel Strips'!$L$28-'Reel Strips'!$L$37)+'Reel Strips'!$H$37*'Reel Strips'!$I$37*'Reel Strips'!$J$37*'Reel Strips'!$K$28*(1-'Reel Strips'!$L$28-'Reel Strips'!$L$37) -> 0.00069522858 | D15: =Paytable!H8 -> 2.4 | E15: =C15*D15*10 -> 0.016685486 | F15: 0.00069522858
A16: Pellets | B16: 5 | C16: ='Reel Strips'!$H$28*('Reel Strips'!$I$28+'Reel Strips'!$I$37)*('Reel Strips'!$J$28+'Reel Strips'!$J$37)*('Reel Strips'!$K$28+'Reel Strips'!$K$37)*('Reel Strips'!$L$28+'Reel Strips'!$L$37)+'Reel Strips'!$H$37*'Reel Strips'!$I$28*('Reel Strips'!$J$28+'Reel Strips'!$J$37)*('Reel Strips'!$K$28+'Reel Strips'!$K$37)*('Reel Strips'!$L$28+'Reel Strips'!$L$37)+'Reel Strips'!$H$37*'Reel Strips'!$I$37*'Reel Strips'!$J$28*('Reel Strips'!$K$28+'Reel Strips'!$K$37)*('Reel Strips'!$L$28+'Reel Strips'!$L$37)+'Reel Strips'!$H$37*'Reel Strips'!$I$37*'Reel Strips'!$J$37*'Reel Strips'!$K$28*('Reel Strips'!$L$28+'Reel Strips'!$L$37)+'Reel Strips'!$H$37*'Reel Strips'!$I$37*'Reel Strips'!$J$37*'Reel Strips'!$K$37*'Reel Strips'!$L$28 -> 0.00012874603 | D16: =Paytable!I8 -> 4.5 | E16: =C16*D16*10 -> 0.0057935715 | F16: 0.00012874603
A17: Flask | B17: 3 | C17: ='Reel Strips'!$H$29*('Reel Strips'!$I$29+'Reel Strips'!$I$37)*('Reel Strips'!$J$29+'Reel Strips'!$J$37)*(1-'Reel Strips'!$K$29-'Reel Strips'!$K$37)+'Reel Strips'!$H$37*'Reel Strips'!$I$29*('Reel Strips'!$J$29+'Reel Strips'!$J$37)*(1-'Reel Strips'!$K$29-'Reel Strips'!$K$37)+'Reel Strips'!$H$37*'Reel Strips'!$I$37*'Reel Strips'!$J$29*(1-'Reel Strips'!$K$29-'Reel Strips'!$K$37) -> 0.0026779175 | D17: =Paytable!G9 -> 1.2 | E17: =C17*D17*10 -> 0.03213501 | F17: 0.0026779175
A18: Flask | B18: 4 | C18: ='Reel Strips'!$H$29*('Reel Strips'!$I$29+'Reel Strips'!$I$37)*('Reel Strips'!$J$29+'Reel Strips'!$J$37)*('Reel Strips'!$K$29+'Reel Strips'!$K$37)*(1-'Reel Strips'!$L$29-'Reel Strips'!$L$37)+'Reel Strips'!$H$37*'Reel Strips'!$I$29*('Reel Strips'!$J$29+'Reel Strips'!$J$37)*('Reel Strips'!$K$29+'Reel Strips'!$K$37)*(1-'Reel Strips'!$L$29-'Reel Strips'!$L$37)+'Reel Strips'!$H$37*'Reel Strips'!$I$37*'Reel Strips'!$J$29*('Reel Strips'!$K$29+'Reel Strips'!$K$37)*(1-'Reel Strips'!$L$29-'Reel Strips'!$L$37)+'Reel Strips'!$H$37*'Reel Strips'!$I$37*'Reel Strips'!$J$37*'Reel Strips'!$K$29*(1-'Reel Strips'!$L$29-'Reel Strips'!$L$37) -> 0.00052142143 | D18: =Paytable!H9 -> 3 | E18: =C18*D18*10 -> 0.015642643 | F18: 0.00052142143
A19: Flask | B19: 5 | C19: ='Reel Strips'!$H$29*('Reel Strips'!$I$29+'Reel Strips'!$I$37)*('Reel Strips'!$J$29+'Reel Strips'!$J$37)*('Reel Strips'!$K$29+'Reel Strips'!$K$37)*('Reel Strips'!$L$29+'Reel Strips'!$L$37)+'Reel Strips'!$H$37*'Reel Strips'!$I$29*('Reel Strips'!$J$29+'Reel Strips'!$J$37)*('Reel Strips'!$K$29+'Reel Strips'!$K$37)*('Reel Strips'!$L$29+'Reel Strips'!$L$37)+'Reel Strips'!$H$37*'Reel Strips'!$I$37*'Reel Strips'!$J$29*('Reel Strips'!$K$29+'Reel Strips'!$K$37)*('Reel Strips'!$L$29+'Reel Strips'!$L$37)+'Reel Strips'!$H$37*'Reel Strips'!$I$37*'Reel Strips'!$J$37*'Reel Strips'!$K$29*('Reel Strips'!$L$29+'Reel Strips'!$L$37)+'Reel Strips'!$H$37*'Reel Strips'!$I$37*'Reel Strips'!$J$37*'Reel Strips'!$K$37*'Reel Strips'!$L$29 -> 9.6559525e-05 | D19: =Paytable!I9 -> 7.5 | E19: =C19*D19*10 -> 0.0072419643 | F19: 9.6559525e-05
A20: Catapult | B20: 3 | C20: ='Reel Strips'!$H$30*('Reel Strips'!$I$30+'Reel Strips'!$I$37)*('Reel Strips'!$J$30+'Reel Strips'!$J$37)*(1-'Reel Strips'!$K$30-'Reel Strips'!$K$37)+'Reel Strips'!$H$37*'Reel Strips'!$I$30*('Reel Strips'!$J$30+'Reel Strips'!$J$37)*(1-'Reel Strips'!$K$30-'Reel Strips'!$K$37)+'Reel Strips'!$H$37*'Reel Strips'!$I$37*'Reel Strips'!$J$30*(1-'Reel Strips'!$K$30-'Reel Strips'!$K$37) -> 0.0019311905 | D20: =Paytable!G10 -> 1.5 | E20: =C20*D20*10 -> 0.028967857 | F20: 0.0019311905
A21: Catapult | B21: 4 | C21: ='Reel Strips'!$H$30*('Reel Strips'!$I$30+'Reel Strips'!$I$37)*('Reel Strips'!$J$30+'Reel Strips'!$J$37)*('Reel Strips'!$K$30+'Reel Strips'!$K$37)*(1-'Reel Strips'!$L$30-'Reel Strips'!$L$37)+'Reel Strips'!$H$37*'Reel Strips'!$I$30*('Reel Strips'!$J$30+'Reel Strips'!$J$37)*('Reel Strips'!$K$30+'Reel Strips'!$K$37)*(1-'Reel Strips'!$L$30-'Reel Strips'!$L$37)+'Reel Strips'!$H$37*'Reel Strips'!$I$37*'Reel Strips'!$J$30*('Reel Strips'!$K$30+'Reel Strips'!$K$37)*(1-'Reel Strips'!$L$30-'Reel Strips'!$L$37)+'Reel Strips'!$H$37*'Reel Strips'!$I$37*'Reel Strips'!$J$37*'Reel Strips'!$K$30*(1-'Reel Strips'!$L$30-'Reel Strips'!$L$37) -> 0.00030174851 | D21: =Paytable!H10 -> 3.6 | E21: =C21*D21*10 -> 0.010862947 | F21: 0.00030174851
A22: Catapult | B22: 5 | C22: ='Reel Strips'!$H$30*('Reel Strips'!$I$30+'Reel Strips'!$I$37)*('Reel Strips'!$J$30+'Reel Strips'!$J$37)*('Reel Strips'!$K$30+'Reel Strips'!$K$37)*('Reel Strips'!$L$30+'Reel Strips'!$L$37)+'Reel Strips'!$H$37*'Reel Strips'!$I$30*('Reel Strips'!$J$30+'Reel Strips'!$J$37)*('Reel Strips'!$K$30+'Reel Strips'!$K$37)*('Reel Strips'!$L$30+'Reel Strips'!$L$37)+'Reel Strips'!$H$37*'Reel Strips'!$I$37*'Reel Strips'!$J$30*('Reel Strips'!$K$30+'Reel Strips'!$K$37)*('Reel Strips'!$L$30+'Reel Strips'!$L$37)+'Reel Strips'!$H$37*'Reel Strips'!$I$37*'Reel Strips'!$J$37*'Reel Strips'!$K$30*('Reel Strips'!$L$30+'Reel Strips'!$L$37)+'Reel Strips'!$H$37*'Reel Strips'!$I$37*'Reel Strips'!$J$37*'Reel Strips'!$K$37*'Reel Strips'!$L$30 -> 5.5879354e-05 | D22: =Paytable!I10 -> 9 | E22: =C22*D22*10 -> 0.0050291419 | F22: 5.5879354e-05
A23: Landing Net | B23: 3 | C23: ='Reel Strips'!$H$31*('Reel Strips'!$I$31+'Reel Strips'!$I$37)*('Reel Strips'!$J$31+'Reel Strips'!$J$37)*(1-'Reel Strips'!$K$31-'Reel Strips'!$K$37)+'Reel Strips'!$H$37*'Reel Strips'!$I$31*('Reel Strips'!$J$31+'Reel Strips'!$J$37)*(1-'Reel Strips'!$K$31-'Reel Strips'!$K$37)+'Reel Strips'!$H$37*'Reel Strips'!$I$37*'Reel Strips'!$J$31*(1-'Reel Strips'!$K$31-'Reel Strips'!$K$37) -> 0.0012874603 | D23: =Paytable!G11 -> 1.8 | E23: =C23*D23*10 -> 0.023174286 | F23: 0.0012874603
A24: Landing Net | B24: 4 | C24: ='Reel Strips'!$H$31*('Reel Strips'!$I$31+'Reel Strips'!$I$37)*('Reel Strips'!$J$31+'Reel Strips'!$J$37)*('Reel Strips'!$K$31+'Reel Strips'!$K$37)*(1-'Reel Strips'!$L$31-'Reel Strips'!$L$37)+'Reel Strips'!$H$37*'Reel Strips'!$I$31*('Reel Strips'!$J$31+'Reel Strips'!$J$37)*('Reel Strips'!$K$31+'Reel Strips'!$K$37)*(1-'Reel Strips'!$L$31-'Reel Strips'!$L$37)+'Reel Strips'!$H$37*'Reel Strips'!$I$37*'Reel Strips'!$J$31*('Reel Strips'!$K$31+'Reel Strips'!$K$37)*(1-'Reel Strips'!$L$31-'Reel Strips'!$L$37)+'Reel Strips'!$H$37*'Reel Strips'!$I$37*'Reel Strips'!$J$37*'Reel Strips'!$K$31*(1-'Reel Strips'!$L$31-'Reel Strips'!$L$37) -> 0.00020861626 | D24: =Paytable!H11 -> 4.5 | E24: =C24*D24*10 -> 0.0093877316 | F24: 0.00020861626
A25: Landing Net | B25: 5 | C25: ='Reel Strips'!$H$31*('Reel Strips'!$I$31+'Reel Strips'!$I$37)*('Reel Strips'!$J$31+'Reel Strips'!$J$37)*('Reel Strips'!$K$31+'Reel Strips'!$K$37)*('Reel Strips'!$L$31+'Reel Strips'!$L$37)+'Reel Strips'!$H$37*'Reel Strips'!$I$31*('Reel Strips'!$J$31+'Reel Strips'!$J$37)*('Reel Strips'!$K$31+'Reel Strips'!$K$37)*('Reel Strips'!$L$31+'Reel Strips'!$L$37)+'Reel Strips'!$H$37*'Reel Strips'!$I$37*'Reel Strips'!$J$31*('Reel Strips'!$K$31+'Reel Strips'!$K$37)*('Reel Strips'!$L$31+'Reel Strips'!$L$37)+'Reel Strips'!$H$37*'Reel Strips'!$I$37*'Reel Strips'!$J$37*'Reel Strips'!$K$31*('Reel Strips'!$L$31+'Reel Strips'!$L$37)+'Reel Strips'!$H$37*'Reel Strips'!$I$37*'Reel Strips'!$J$37*'Reel Strips'!$K$37*'Reel Strips'!$L$31 -> 2.9802322e-05 | D25: =Paytable!I11 -> 12 | E25: =C25*D25*10 -> 0.0035762787 | F25: 2.9802322e-05
A26: Bivvy | B26: 3 | C26: ='Reel Strips'!$H$32*('Reel Strips'!$I$32+'Reel Strips'!$I$37)*('Reel Strips'!$J$32+'Reel Strips'!$J$37)*(1-'Reel Strips'!$K$32-'Reel Strips'!$K$37)+'Reel Strips'!$H$37*'Reel Strips'!$I$32*('Reel Strips'!$J$32+'Reel Strips'!$J$37)*(1-'Reel Strips'!$K$32-'Reel Strips'!$K$37)+'Reel Strips'!$H$37*'Reel Strips'!$I$37*'Reel Strips'!$J$32*(1-'Reel Strips'!$K$32-'Reel Strips'!$K$37) -> 0.0012874603 | D26: =Paytable!G12 -> 2.4 | E26: =C26*D26*10 -> 0.030899048 | F26: 0.0012874603
A27: Bivvy | B27: 4 | C27: ='Reel Strips'!$H$32*('Reel Strips'!$I$32+'Reel Strips'!$I$37)*('Reel Strips'!$J$32+'Reel Strips'!$J$37)*('Reel Strips'!$K$32+'Reel Strips'!$K$37)*(1-'Reel Strips'!$L$32-'Reel Strips'!$L$37)+'Reel Strips'!$H$37*'Reel Strips'!$I$32*('Reel Strips'!$J$32+'Reel Strips'!$J$37)*('Reel Strips'!$K$32+'Reel Strips'!$K$37)*(1-'Reel Strips'!$L$32-'Reel Strips'!$L$37)+'Reel Strips'!$H$37*'Reel Strips'!$I$37*'Reel Strips'!$J$32*('Reel Strips'!$K$32+'Reel Strips'!$K$37)*(1-'Reel Strips'!$L$32-'Reel Strips'!$L$37)+'Reel Strips'!$H$37*'Reel Strips'!$I$37*'Reel Strips'!$J$37*'Reel Strips'!$K$32*(1-'Reel Strips'!$L$32-'Reel Strips'!$L$37) -> 0.00020861626 | D27: =Paytable!H12 -> 6 | E27: =C27*D27*10 -> 0.012516975 | F27: 0.00020861626
A28: Bivvy | B28: 5 | C28: ='Reel Strips'!$H$32*('Reel Strips'!$I$32+'Reel Strips'!$I$37)*('Reel Strips'!$J$32+'Reel Strips'!$J$37)*('Reel Strips'!$K$32+'Reel Strips'!$K$37)*('Reel Strips'!$L$32+'Reel Strips'!$L$37)+'Reel Strips'!$H$37*'Reel Strips'!$I$32*('Reel Strips'!$J$32+'Reel Strips'!$J$37)*('Reel Strips'!$K$32+'Reel Strips'!$K$37)*('Reel Strips'!$L$32+'Reel Strips'!$L$37)+'Reel Strips'!$H$37*'Reel Strips'!$I$37*'Reel Strips'!$J$32*('Reel Strips'!$K$32+'Reel Strips'!$K$37)*('Reel Strips'!$L$32+'Reel Strips'!$L$37)+'Reel Strips'!$H$37*'Reel Strips'!$I$37*'Reel Strips'!$J$37*'Reel Strips'!$K$32*('Reel Strips'!$L$32+'Reel Strips'!$L$37)+'Reel Strips'!$H$37*'Reel Strips'!$I$37*'Reel Strips'!$J$37*'Reel Strips'!$K$37*'Reel Strips'!$L$32 -> 2.9802322e-05 | D28: =Paytable!I12 -> 15 | E28: =C28*D28*10 -> 0.0044703484 | F28: 2.9802322e-05
A29: Roach | B29: 3 | C29: ='Reel Strips'!$H$33*('Reel Strips'!$I$33+'Reel Strips'!$I$37)*('Reel Strips'!$J$33+'Reel Strips'!$J$37)*(1-'Reel Strips'!$K$33-'Reel Strips'!$K$37)+'Reel Strips'!$H$37*'Reel Strips'!$I$33*('Reel Strips'!$J$33+'Reel Strips'!$J$37)*(1-'Reel Strips'!$K$33-'Reel Strips'!$K$37)+'Reel Strips'!$H$37*'Reel Strips'!$I$37*'Reel Strips'!$J$33*(1-'Reel Strips'!$K$33-'Reel Strips'!$K$37) -> 0.00042724609 | D29: =Paytable!G13 -> 3 | E29: =C29*D29*10 -> 0.012817383 | F29: 0.00042724609
A30: Roach | B30: 4 | C30: ='Reel Strips'!$H$33*('Reel Strips'!$I$33+'Reel Strips'!$I$37)*('Reel Strips'!$J$33+'Reel Strips'!$J$37)*('Reel Strips'!$K$33+'Reel Strips'!$K$37)*(1-'Reel Strips'!$L$33-'Reel Strips'!$L$37)+'Reel Strips'!$H$37*'Reel Strips'!$I$33*('Reel Strips'!$J$33+'Reel Strips'!$J$37)*('Reel Strips'!$K$33+'Reel Strips'!$K$37)*(1-'Reel Strips'!$L$33-'Reel Strips'!$L$37)+'Reel Strips'!$H$37*'Reel Strips'!$I$37*'Reel Strips'!$J$33*('Reel Strips'!$K$33+'Reel Strips'!$K$37)*(1-'Reel Strips'!$L$33-'Reel Strips'!$L$37)+'Reel Strips'!$H$37*'Reel Strips'!$I$37*'Reel Strips'!$J$37*'Reel Strips'!$K$33*(1-'Reel Strips'!$L$33-'Reel Strips'!$L$37) -> 5.531311e-05 | D30: =Paytable!H13 -> 7.5 | E30: =C30*D30*10 -> 0.0041484833 | F30: 5.531311e-05
A31: Roach | B31: 5 | C31: ='Reel Strips'!$H$33*('Reel Strips'!$I$33+'Reel Strips'!$I$37)*('Reel Strips'!$J$33+'Reel Strips'!$J$37)*('Reel Strips'!$K$33+'Reel Strips'!$K$37)*('Reel Strips'!$L$33+'Reel Strips'!$L$37)+'Reel Strips'!$H$37*'Reel Strips'!$I$33*('Reel Strips'!$J$33+'Reel Strips'!$J$37)*('Reel Strips'!$K$33+'Reel Strips'!$K$37)*('Reel Strips'!$L$33+'Reel Strips'!$L$37)+'Reel Strips'!$H$37*'Reel Strips'!$I$37*'Reel Strips'!$J$33*('Reel Strips'!$K$33+'Reel Strips'!$K$37)*('Reel Strips'!$L$33+'Reel Strips'!$L$37)+'Reel Strips'!$H$37*'Reel Strips'!$I$37*'Reel Strips'!$J$37*'Reel Strips'!$K$33*('Reel Strips'!$L$33+'Reel Strips'!$L$37)+'Reel Strips'!$H$37*'Reel Strips'!$I$37*'Reel Strips'!$J$37*'Reel Strips'!$K$37*'Reel Strips'!$L$33 -> 5.7220459e-06 | D31: =Paytable!I13 -> 18 | E31: =C31*D31*10 -> 0.0010299683 | F31: 5.7220459e-06
A32: Bream | B32: 3 | C32: ='Reel Strips'!$H$34*('Reel Strips'!$I$34+'Reel Strips'!$I$37)*('Reel Strips'!$J$34+'Reel Strips'!$J$37)*(1-'Reel Strips'!$K$34-'Reel Strips'!$K$37)+'Reel Strips'!$H$37*'Reel Strips'!$I$34*('Reel Strips'!$J$34+'Reel Strips'!$J$37)*(1-'Reel Strips'!$K$34-'Reel Strips'!$K$37)+'Reel Strips'!$H$37*'Reel Strips'!$I$37*'Reel Strips'!$J$34*(1-'Reel Strips'!$K$34-'Reel Strips'!$K$37) -> 0.00042724609 | D32: =Paytable!G14 -> 3.6 | E32: =C32*D32*10 -> 0.015380859 | F32: 0.00042724609
A33: Bream | B33: 4 | C33: ='Reel Strips'!$H$34*('Reel Strips'!$I$34+'Reel Strips'!$I$37)*('Reel Strips'!$J$34+'Reel Strips'!$J$37)*('Reel Strips'!$K$34+'Reel Strips'!$K$37)*(1-'Reel Strips'!$L$34-'Reel Strips'!$L$37)+'Reel Strips'!$H$37*'Reel Strips'!$I$34*('Reel Strips'!$J$34+'Reel Strips'!$J$37)*('Reel Strips'!$K$34+'Reel Strips'!$K$37)*(1-'Reel Strips'!$L$34-'Reel Strips'!$L$37)+'Reel Strips'!$H$37*'Reel Strips'!$I$37*'Reel Strips'!$J$34*('Reel Strips'!$K$34+'Reel Strips'!$K$37)*(1-'Reel Strips'!$L$34-'Reel Strips'!$L$37)+'Reel Strips'!$H$37*'Reel Strips'!$I$37*'Reel Strips'!$J$37*'Reel Strips'!$K$34*(1-'Reel Strips'!$L$34-'Reel Strips'!$L$37) -> 5.531311e-05 | D33: =Paytable!H14 -> 9 | E33: =C33*D33*10 -> 0.0049781799 | F33: 5.531311e-05
A34: Bream | B34: 5 | C34: ='Reel Strips'!$H$34*('Reel Strips'!$I$34+'Reel Strips'!$I$37)*('Reel Strips'!$J$34+'Reel Strips'!$J$37)*('Reel Strips'!$K$34+'Reel Strips'!$K$37)*('Reel Strips'!$L$34+'Reel Strips'!$L$37)+'Reel Strips'!$H$37*'Reel Strips'!$I$34*('Reel Strips'!$J$34+'Reel Strips'!$J$37)*('Reel Strips'!$K$34+'Reel Strips'!$K$37)*('Reel Strips'!$L$34+'Reel Strips'!$L$37)+'Reel Strips'!$H$37*'Reel Strips'!$I$37*'Reel Strips'!$J$34*('Reel Strips'!$K$34+'Reel Strips'!$K$37)*('Reel Strips'!$L$34+'Reel Strips'!$L$37)+'Reel Strips'!$H$37*'Reel Strips'!$I$37*'Reel Strips'!$J$37*'Reel Strips'!$K$34*('Reel Strips'!$L$34+'Reel Strips'!$L$37)+'Reel Strips'!$H$37*'Reel Strips'!$I$37*'Reel Strips'!$J$37*'Reel Strips'!$K$37*'Reel Strips'!$L$34 -> 5.7220459e-06 | D34: =Paytable!I14 -> 24 | E34: =C34*D34*10 -> 0.001373291 | F34: 5.7220459e-06
A35: Tench | B35: 3 | C35: ='Reel Strips'!$H$35*('Reel Strips'!$I$35+'Reel Strips'!$I$37)*('Reel Strips'!$J$35+'Reel Strips'!$J$37)*(1-'Reel Strips'!$K$35-'Reel Strips'!$K$37)+'Reel Strips'!$H$37*'Reel Strips'!$I$35*('Reel Strips'!$J$35+'Reel Strips'!$J$37)*(1-'Reel Strips'!$K$35-'Reel Strips'!$K$37)+'Reel Strips'!$H$37*'Reel Strips'!$I$37*'Reel Strips'!$J$35*(1-'Reel Strips'!$K$35-'Reel Strips'!$K$37) -> 0.00042724609 | D35: =Paytable!G15 -> 4.5 | E35: =C35*D35*10 -> 0.019226074 | F35: 0.00042724609
A36: Tench | B36: 4 | C36: ='Reel Strips'!$H$35*('Reel Strips'!$I$35+'Reel Strips'!$I$37)*('Reel Strips'!$J$35+'Reel Strips'!$J$37)*('Reel Strips'!$K$35+'Reel Strips'!$K$37)*(1-'Reel Strips'!$L$35-'Reel Strips'!$L$37)+'Reel Strips'!$H$37*'Reel Strips'!$I$35*('Reel Strips'!$J$35+'Reel Strips'!$J$37)*('Reel Strips'!$K$35+'Reel Strips'!$K$37)*(1-'Reel Strips'!$L$35-'Reel Strips'!$L$37)+'Reel Strips'!$H$37*'Reel Strips'!$I$37*'Reel Strips'!$J$35*('Reel Strips'!$K$35+'Reel Strips'!$K$37)*(1-'Reel Strips'!$L$35-'Reel Strips'!$L$37)+'Reel Strips'!$H$37*'Reel Strips'!$I$37*'Reel Strips'!$J$37*'Reel Strips'!$K$35*(1-'Reel Strips'!$L$35-'Reel Strips'!$L$37) -> 5.531311e-05 | D36: =Paytable!H15 -> 12 | E36: =C36*D36*10 -> 0.0066375732 | F36: 5.531311e-05
A37: Tench | B37: 5 | C37: ='Reel Strips'!$H$35*('Reel Strips'!$I$35+'Reel Strips'!$I$37)*('Reel Strips'!$J$35+'Reel Strips'!$J$37)*('Reel Strips'!$K$35+'Reel Strips'!$K$37)*('Reel Strips'!$L$35+'Reel Strips'!$L$37)+'Reel Strips'!$H$37*'Reel Strips'!$I$35*('Reel Strips'!$J$35+'Reel Strips'!$J$37)*('Reel Strips'!$K$35+'Reel Strips'!$K$37)*('Reel Strips'!$L$35+'Reel Strips'!$L$37)+'Reel Strips'!$H$37*'Reel Strips'!$I$37*'Reel Strips'!$J$35*('Reel Strips'!$K$35+'Reel Strips'!$K$37)*('Reel Strips'!$L$35+'Reel Strips'!$L$37)+'Reel Strips'!$H$37*'Reel Strips'!$I$37*'Reel Strips'!$J$37*'Reel Strips'!$K$35*('Reel Strips'!$L$35+'Reel Strips'!$L$37)+'Reel Strips'!$H$37*'Reel Strips'!$I$37*'Reel Strips'!$J$37*'Reel Strips'!$K$37*'Reel Strips'!$L$35 -> 5.7220459e-06 | D37: =Paytable!I15 -> 36 | E37: =C37*D37*10 -> 0.0020599365 | F37: 5.7220459e-06
A38: Mirror Carp | B38: 3 | C38: ='Reel Strips'!$H$36*('Reel Strips'!$I$36+'Reel Strips'!$I$37)*('Reel Strips'!$J$36+'Reel Strips'!$J$37)*(1-'Reel Strips'!$K$36-'Reel Strips'!$K$37)+'Reel Strips'!$H$37*'Reel Strips'!$I$36*('Reel Strips'!$J$36+'Reel Strips'!$J$37)*(1-'Reel Strips'!$K$36-'Reel Strips'!$K$37)+'Reel Strips'!$H$37*'Reel Strips'!$I$37*'Reel Strips'!$J$36*(1-'Reel Strips'!$K$36-'Reel Strips'!$K$37) -> 0.00042724609 | D38: =Paytable!G16 -> 6 | E38: =C38*D38*10 -> 0.025634766 | F38: 0.00042724609
